Workbook

Sheet Orders
A1: Sales Orders FY2024
A3: Order ID | B3: Order Date | C3: Customer ID | D3: SKU | E3: Region | F3: Units | G3: Unit Price | H3: Discount | I3: Revenue | J3: Status | K3: Unit Cost | L3: Margin %
A4: 10000 | B4: 45372 | C4: 47 | D4: SKU-1020 | E4: West | F4: 33 | G4: 93.03 | H4: 0.05 | I4: =F4*G4*(1-H4) -> 2916.4905 | J4: Shipped | K4: =VLOOKUP(D4,Products!$A$2:$E$26,4,FALSE()) -> 39.86 | L4: =(I4-F4*K4)/I4 -> 0.54898533
A5: 10001 | B5: 45459 | C5: 35 | D5: SKU-1017 | E5: West | F5: 13 | G5: 139.19 | H5: 0 | I5: =F5*G5*(1-H5) -> 1809.47 | J5: Shipped | K5: =VLOOKUP(D5,Products!$A$2:$E$26,4,FALSE()) -> 72.1 | L5: =(I5-F5*K5)/I5 -> 0.48200302
A6: 10002 | B6: 45333 | C6: 55 | D6: SKU-1003 | E6: West | F6: 4 | G6: 89.24 | H6: 0 | I6: =F6*G6*(1-H6) -> 356.96 | J6: Pending | K6: =VLOOKUP(D6,Products!$A$2:$E$26,4,FALSE()) -> 38.24 | L6: =(I6-F6*K6)/I6 -> 0.5714926
A7: 10003 | B7: 45411 | C7: 27 | D7: SKU-1014 | E7: North | F7: 34 | G7: 216.62 | H7: 0.1 | I7: =F7*G7*(1-H7) -> 6628.572 | J7: Pending | K7: =VLOOKUP(D7,Products!$A$2:$E$26,4,FALSE()) -> 83.93 | L7: =(I7-F7*K7)/I7 -> 0.56949702
A8: 10004 | B8: 45638 | C8: 39 | D8: SKU-1020 | E8: East | F8: 32 | G8: 94.57 | H8: 0 | I8: =F8*G8*(1-H8) -> 3026.24 | J8: Shipped | K8: =VLOOKUP(D8,Products!$A$2:$E$26,4,FALSE()) -> 39.86 | L8: =(I8-F8*K8)/I8 -> 0.57851327
A9: 10005 | B9: 45452 | C9: 61 | D9: SKU-1017 | E9: North | F9: 16 | G9: 141.9 | H9: 0 | I9: =F9*G9*(1-H9) -> 2270.4 | J9: Pending | K9: =VLOOKUP(D9,Products!$A$2:$E$26,4,FALSE()) -> 72.1 | L9: =(I9-F9*K9)/I9 -> 0.4918957
A10: 10006 | B10: 45468 | C10: 80 | D10: SKU-1004 | E10: East | F10: 35 | G10: 47.47 | H10: 0.1 | I10: =F10*G10*(1-H10) -> 1495.305 | J10: Shipped | K10: =VLOOKUP(D10,Products!$A$2:$E$26,4,FALSE()) -> 26.06 | L10: =(I10-F10*K10)/I10 -> 0.39002411
A11: 10007 | B11: 45437 | C11: 80 | D11: SKU-1000 | E11: South | F11: 21 | G11: 125 | H11: 0 | I11: =F11*G11*(1-H11) -> 2625 | J11: Shipped | K11: =VLOOKUP(D11,Products!$A$2:$E$26,4,FALSE()) -> 75.38 | L11: =(I11-F11*K11)/I11 -> 0.39696
A12: 10008 | B12: 45319 | C12: 13 | D12: SKU-1005 | E12: South | F12: 31 | G12: 206.69 | H12: 0.15 | I12: =F12*G12*(1-H12) -> 5446.2815 | J12: Shipped | K12: =VLOOKUP(D12,Products!$A$2:$E$26,4,FALSE()) -> 128.85 | L12: =(I12-F12*K12)/I12 -> 0.26659134
A13: 10009 | B13: 45504 | C13: 18 | D13: SKU-1004 | E13: East | F13: 24 | G13: 47.83 | H13: 0 | I13: =F13*G13*(1-H13) -> 1147.92 | J13: Shipped | K13: =VLOOKUP(D13,Products!$A$2:$E$26,4,FALSE()) -> 26.06 | L13: =(I13-F13*K13)/I13 -> 0.45515367
A14: 10010 | B14: 45596 | C14: 58 | D14: SKU-1019 | E14: South | F14: 21 | G14: 53.86 | H14: 0 | I14: =F14*G14*(1-H14) -> 1131.06 | J14: Pending | K14: =VLOOKUP(D14,Products!$A$2:$E$26,4,FALSE()) -> 22.68 | L14: =(I14-F14*K14)/I14 -> 0.57890828
A15: 10011 | B15: 45552 | C15: 57 | D15: SKU-1024 | E15: South | F15: 13 | G15: 115.73 | H15: 0 | I15: =F15*G15*(1-H15) -> 1504.49 | J15: Returned | K15: =VLOOKUP(D15,Products!$A$2:$E$26,4,FALSE()) -> 45.07 | L15: =(I15-F15*K15)/I15 -> 0.61055906
... A34: 10030 | B34: 45530 | C34: 59 | D34: SKU-1004 | E34: South | F34: 7 | G34: 50.86 | H34: 0.1 | I34: =F34*G34*(1-H34) -> 320.418 | J34: Pending | K34: =VLOOKUP(D34,Products!$A$2:$E$26,4,FALSE()) -> 26.06 | L34: =(I34-F34*K34)/I34 -> 0.43068117
A35: 10031 | B35: 45560 | C35: 42 | D35: SKU-1015 | E35: East | F35: 37 | G35: 179.75 | H35: 0 | I35: =F35*G35*(1-H35) -> 6650.75 | J35: Returned | K35: =VLOOKUP(D35,Products!$A$2:$E$26,4,FALSE()) -> 107.25 | L35: =(I35-F35*K35)/I35 -> 0.40333797
A36: 10032 | B36: 45555 | C36: 79 | D36: SKU-1007 | E36: North | F36: 27 | G36: 41.73 | H36: 0 | I36: =F36*G36*(1-H36) -> 1126.71 | J36: Shipped | K36: =VLOOKUP(D36,Products!$A$2:$E$26,4,FALSE()) -> 23.25 | L36: =(I36-F36*K36)/I36 -> 0.44284687
A37: 10033 | B37: 45582 | C37: 21 | D37: SKU-1023 | E37: South | F37: 37 | G37: 404.69 | H37: 0 | I37: =F37*G37*(1-H37) -> 14973.53 | J37: Shipped | K37: =VLOOKUP(D37,Products!$A$2:$E$26,4,FALSE()) -> 244.6 | L37: =(I37-F37*K37)/I37 -> 0.39558675
A38: 10034 | B38: 45628 | C38: 45 | D38: SKU-1014 | E38: North | F38: 34 | G38: 209.82 | H38: 0.15 | I38: =F38*G38*(1-H38) -> 6063.798 | J38: Shipped | K38: =VLOOKUP(D38,Products!$A$2:$E$26,4,FALSE()) -> 83.93 | L38: =(I38-F38*K38)/I38 -> 0.52940055
A39: 10035 | B39: 45396 | C39: 80 | D39: SKU-1000 | E39: North | F39: 13 | G39: 123.85 | H39: 0.15 | I39: =F39*G39*(1-H39) -> 1368.5425 | J39: Shipped | K39: =VLOOKUP(D39,Products!$A$2:$E$26,4,FALSE()) -> 75.38 | L39: =(I39-F39*K39)/I39 -> 0.28395355
A40: 10036 | B40: 45506 | C40: 11 | D40: SKU-1016 | E40: North | F40: 10 | G40: 25.86 | H40: 0.05 | I40: =F40*G40*(1-H40) -> 245.67 | J40: Pending | K40: =VLOOKUP(D40,Products!$A$2:$E$26,4,FALSE()) -> 12.46 | L40: =(I40-F40*K40)/I40 -> 0.49281557
A41: 10037 | B41: 45568 | C41: 44 | D41: SKU-1023 | E41: West | F41: 6 | G41: 390.88 | H41: 0 | I41: =F41*G41*(1-H41) -> 2345.28 | J41: Shipped | K41: =VLOOKUP(D41,Products!$A$2:$E$26,4,FALSE()) -> 244.6 | L41: =(I41-F41*K41)/I41 -> 0.3742325
A42: 10038 | B42: 45496 | C42: 28 | D42: SKU-1015 | E42: East | F42: 11 | G42: 180.86 | H42: 0 | I42: =F42*G42*(1-H42) -> 1989.46 | J42: Shipped | K42: =VLOOKUP(D42,Products!$A$2:$E$26,4,FALSE()) -> 107.25 | L42: =(I42-F42*K42)/I42 -> 0.40699989
A43: 10039 | B43: 45459 | C43: 69 | D43: SKU-1024 | E43: North | F43: 21 | G43: 115.7 | H43: 0 | I43: =F43*G43*(1-H43) -> 2429.7 | J43: Pending | K43: =VLOOKUP(D43,Products!$A$2:$E$26,4,FALSE()) -> 45.07 | L43: =(I43-F43*K43)/I43 -> 0.61045808
A44: 10040 | B44: 45555 | C44: 57 | D44: SKU-1005 | E44: West | F44: 16 | G44: 203.24 | H44: 0.05 | I44: =F44*G44*(1-H44) -> 3089.248 | J44: Shipped | K44: =VLOOKUP(D44,Products!$A$2:$E$26,4,FALSE()) -> 128.85 | L44: =(I44-F44*K44)/I44 -> 0.33265312
A45: 10041 | B45: 45347 | C45: 22 | D45: SKU-1009 | E45: East | F45: 14 | G45: 78.19 | H45: 0 | I45: =F45*G45*(1-H45) -> 1094.66 | J45: Returned | K45: =VLOOKUP(D45,Products!$A$2:$E$26,4,FALSE()) -> 47.32 | L45: =(I45-F45*K45)/I45 -> 0.39480752
A46: 10042 | B46: 45344 | C46: 24 | D46: SKU-1002 | E46: East | F46: 8 | G46: 218.75 | H46: 0 | I46: =F46*G46*(1-H46) -> 1750 | J46: Shipped | K46: =VLOOKUP(D46,Products!$A$2:$E$26,4,FALSE()) -> 126.91 | L46: =(I46-F46*K46)/I46 -> 0.41984
A47: 10043 | B47: 45394 | C47: 78 | D47: SKU-1019 | E47: West | F47: 33 | G47: 51.7 | H47: 0.05 | I47: =F47*G47*(1-H47) -> 1620.795 | J47: Shipped | K47: =VLOOKUP(D47,Products!$A$2:$E$26,4,FALSE()) -> 22.68 | L47: =(I47-F47*K47)/I47 -> 0.53822661
A48: 10044 | B48: 45556 | C48: 50 | D48: SKU-1011 | E48: South | F48: 18 | G48: 354.37 | H48: 0 | I48: =F48*G48*(1-H48) -> 6378.66 | J48: Shipped | K48: =VLOOKUP(D48,Products!$A$2:$E$26,4,FALSE()) -> 144.3 | L48: =(I48-F48*K48)/I48 -> 0.59279849
... A336: 10332 | B336: 45650 | C336: 32 | D336: SKU-1024 | E336: West | F336: 18 | G336: 116.39 | H336: 0.15 | I336: =F336*G336*(1-H336) -> 1780.767 | J336: Pending | K336: =VLOOKUP(D336,Products!$A$2:$E$26,4,FALSE()) -> 45.07 | L336: =(I336-F336*K336)/I336 -> 0.54443226
A337: 10333 | B337: 45421 | C337: 47 | D337: SKU-1016 | E337: South | F337: 35 | G337: 25.16 | H337: 0.15 | I337: =F337*G337*(1-H337) -> 748.51 | J337: Shipped | K337: =VLOOKUP(D337,Products!$A$2:$E$26,4,FALSE()) -> 12.46 | L337: =(I337-F337*K337)/I337 -> 0.41737585
A338: 10334 | B338: 45554 | C338: 37 | D338: SKU-1005 | E338: North | F338: 11 | G338: 206 | H338: 0.05 | I338: =F338*G338*(1-H338) -> 2152.7 | J338: Pending | K338: =VLOOKUP(D338,Products!$A$2:$E$26,4,FALSE()) -> 128.85 | L338: =(I338-F338*K338)/I338 -> 0.34159428
A339: 10335 | B339: 45656 | C339: 73 | D339: SKU-1015 | E339: West | F339: 4 | G339: 180.43 | H339: 0 | I339: =F339*G339*(1-H339) -> 721.72 | J339: Shipped | K339: =VLOOKUP(D339,Products!$A$2:$E$26,4,FALSE()) -> 107.25 | L339: =(I339-F339*K339)/I339 -> 0.40558665
A340: 10336 | B340: 45551 | C340: 25 | D340: SKU-1001 | E340: North | F340: 33 | G340: 21.01 | H340: 0 | I340: =F340*G340*(1-H340) -> 693.33 | J340: Shipped | K340: =VLOOKUP(D340,Products!$A$2:$E$26,4,FALSE()) -> 14.34 | L340: =(I340-F340*K340)/I340 -> 0.31746787
A341: 10337 | B341: 45638 | C341: 68 | D341: SKU-1020 | E341: South | F341: 29 | G341: 95.44 | H341: 0.1 | I341: =F341*G341*(1-H341) -> 2490.984 | J341: Shipped | K341: =VLOOKUP(D341,Products!$A$2:$E$26,4,FALSE()) -> 39.86 | L341: =(I341-F341*K341)/I341 -> 0.53595045
A342: 10338 | B342: 45500 | C342: 54 | D342: SKU-1015 | E342: East | F342: 36 | G342: 180.8 | H342: 0.05 | I342: =F342*G342*(1-H342) -> 6183.36 | J342: Shipped | K342: =VLOOKUP(D342,Products!$A$2:$E$26,4,FALSE()) -> 107.25 | L342: =(I342-F342*K342)/I342 -> 0.37558221
A343: 10339 | B343: 45465 | C343: 41 | D343: SKU-1001 | E343: East | F343: 34 | G343: 22.43 | H343: 0 | I343: =F343*G343*(1-H343) -> 762.62 | J343: Pending | K343: =VLOOKUP(D343,Products!$A$2:$E$26,4,FALSE()) -> 14.34 | L343: =(I343-F343*K343)/I343 -> 0.36067766
A344: 10340 | B344: 45431 | C344: 54 | D344: SKU-1004 | E344: North | F344: 10 | G344: 49.39 | H344: 0.05 | I344: =F344*G344*(1-H344) -> 469.205 | J344: Pending | K344: =VLOOKUP(D344,Products!$A$2:$E$26,4,FALSE()) -> 26.06 | L344: =(I344-F344*K344)/I344 -> 0.44459245
A345: 10341 | B345: 45640 | C345: 63 | D345: SKU-1014 | E345: North | F345: 8 | G345: 205.84 | H345: 0.05 | I345: =F345*G345*(1-H345) -> 1564.384 | J345: Returned | K345: =VLOOKUP(D345,Products!$A$2:$E$26,4,FALSE()) -> 83.93 | L345: =(I345-F345*K345)/I345 -> 0.57079592
A346: 10342 | B346: 45315 | C346: 44 | D346: SKU-1014 | E346: East | F346: 38 | G346: 216.75 | H346: 0.05 | I346: =F346*G346*(1-H346) -> 7824.675 | J346: Shipped | K346: =VLOOKUP(D346,Products!$A$2:$E$26,4,FALSE()) -> 83.93 | L346: =(I346-F346*K346)/I346 -> 0.59239968
...

Sheet Products
A1: SKU | B1: Product Name | C1: Category | D1: Unit Cost | E1: List Price
A2: SKU-1000 | B2: Hardware item 1 | C2: Hardware | D2: 75.38 | E2: 124.62
A3: SKU-1001 | B3: Software item 2 | C3: Software | D3: 14.34 | E3: 21.71
A4: SKU-1002 | B4: Services item 3 | C4: Services | D4: 126.91 | E4: 211.23
A5: SKU-1003 | B5: Hardware item 4 | C5: Hardware | D5: 38.24 | E5: 87.74
A6: SKU-1004 | B6: Software item 5 | C6: Software | D6: 26.06 | E6: 49.69
A7: SKU-1005 | B7: Services item 6 | C7: Services | D7: 128.85 | E7: 213.08
A8: SKU-1006 | B8: Hardware item 7 | C8: Hardware | D8: 97.8 | E8: 213.38
A9: SKU-1007 | B9: Software item 8 | C9: Software | D9: 23.25 | E9: 43.72
A10: SKU-1008 | B10: Services item 9 | C10: Services | D10: 219.79 | E10: 314.04
A11: SKU-1009 | B11: Hardware item 10 | C11: Hardware | D11: 47.32 | E11: 77.15
A12: SKU-1010 | B12: Software item 11 | C12: Software | D12: 18.41 | E12: 30.77
A13: SKU-1011 | B13: Services item 12 | C13: Services | D13: 144.3 | E13: 359.01
... A26: SKU-1024 | B26: Hardware item 25 | C26: Hardware | D26: 45.07 | E26: 115.79

Sheet Customers
A1: Customer ID | B1: Name | C1: Email | D1: Segment | E1: Country | F1: Signup Date
A2: 1 | B2: Omar Garcia | C2: omar.garcia1@example.com | D2: SMB | E2: US | F2: 44672
A3: 2 | B3: Iris Okafor | C3: iris.okafor2@example.com | D3: Consumer | E3: DE | F3: 44702
A4: 3 | B4: Zoe Kim | C4: zoe.kim3@example.com | D4: Consumer | E4: US | F4: 44593
A5: 4 | B5: Sofia Chen | C5: sofia.chen4@example.com | D5: Enterprise | E5: DE | F5: 45078
A6: 5 | B6: Zoe Okafor | C6: zoe.okafor5@example.com | D6: Enterprise | E6: GB | F6: 45143
A7: 6 | B7: Maya Nguyen | C7: maya.nguyen6@example.com | D7: Enterprise | E7: US | F7: 45160
A8: 7 | B8: Zoe Chen | C8: zoe.chen7@example.com | D8: Enterprise | E8: US | F8: 44917
A9: 8 | B9: Omar Nguyen | C9: omar.nguyen8@example.com | D9: SMB | E9: US | F9: 44397
A10: 9 | B10: Priya Novak | C10: priya.novak9@example.com | D10: SMB | E10: GB | F10: 44466
A11: 10 | B11: Leo Rossi | C11: leo.rossi10@example.com | D11: Enterprise | E11: US | F11: 44402
A12: 11 | B12: Ravi Kim | C12: ravi.kim11@example.com | D12: Consumer | E12: DE | F12: 44336
A13: 12 | B13: Lena Silva | C13: lena.silva12@example.com | D13: SMB | E13: US | F13: 44300
... A81: 80 | B81: Ravi Smith | C81: ravi.smith80@example.com | D81: Consumer | E81: CA | F81: 44589

Sheet Targets
A1: Region | B1: Jan | C1: Feb | D1: Mar | E1: Apr | F1: May | G1: Jun | H1: Jul | I1: Aug | J1: Sep | K1: Oct | L1: Nov | M1: Dec
A2: West | B2: 21000 | C2: 21000 | D2: 21000 | E2: 22000 | F2: 22000 | G2: 23000 | H2: 23000 | I2: 24000 | J2: 24000 | K2: 24000 | L2: 25000 | M2: 25000
A3: East | B3: 19000 | C3: 19000 | D3: 20000 | E3: 20000 | F3: 21000 | G3: 21000 | H3: 21000 | I3: 22000 | J3: 22000 | K3: 23000 | L3: 23000 | M3: 23000
A4: North | B4: 28000 | C4: 28000 | D4: 29000 | E4: 29000 | F4: 30000 | G4: 30000 | H4: 31000 | I4: 31000 | J4: 32000 | K4: 33000 | L4: 33000 | M4: 34000
A5: South | B5: 20000 | C5: 21000 | D5: 21000 | E5: 22000 | F5: 22000 | G5: 22000 | H5: 23000 | I5: 23000 | J5: 24000 | K5: 24000 | L5: 24000 | M5: 25000
A8: EUR/USD | B8: 1.09

Sheet Lookups
A1: Status | B1: Counts As Sale
A2: Shipped | B2: =TRUE() -> TRUE
A3: Pending | B3: =FALSE() -> FALSE
A4: Returned | B4: =FALSE() -> FALSE
